<sdf version='1.6'>
  <world name='default'>
    <light name='sun' type='directional'>
      <cast_shadows>1</cast_shadows>
      <pose frame=''>0 0 10 0 -0 0</pose>
      <diffuse>0.8 0.8 0.8 1</diffuse>
      <specular>0.1 0.1 0.1 1</specular>
      <attenuation>
        <range>1000</range>
        <constant>0.9</constant>
        <linear>0.01</linear>
        <quadratic>0.001</quadratic>
      </attenuation>
      <direction>-0.5 0.5 -1</direction>
    </light>
    <model name='ground_plane'>
      <static>1</static>
      <link name='link'>
        <collision name='collision'>
          <geometry>
            <plane>
              <normal>0 0 1</normal>
              <size>100 100</size>
            </plane>
          </geometry>
          <surface>
            <friction>
              <ode>
                <mu>100</mu>
                <mu2>50</mu2>
              </ode>
              <torsional>
                <ode/>
              </torsional>
            </friction>
            <contact>
              <ode/>
            </contact>
            <bounce/>
          </surface>
          <max_contacts>10</max_contacts>
        </collision>
        <visual name='visual'>
          <cast_shadows>0</cast_shadows>
          <geometry>
            <plane>
              <normal>0 0 1</normal>
              <size>100 100</size>
            </plane>
          </geometry>
          <material>
            <script>
              <uri>file://media/materials/scripts/gazebo.material</uri>
              <name>Gazebo/Grey</name>
            </script>
          </material>
        </visual>
        <self_collide>0</self_collide>
        <kinematic>0</kinematic>
        <gravity>1</gravity>
      </link>
    </model>
    <gravity>0 0 -9.8</gravity>
    <magnetic_field>6e-06 2.3e-05 -4.2e-05</magnetic_field>
    <atmosphere type='adiabatic'/>
    <physics name='default_physics' default='0' type='ode'>
      <max_step_size>0.001</max_step_size>
      <real_time_factor>1</real_time_factor>
      <real_time_update_rate>1000</real_time_update_rate>
    </physics>
    <scene>
      <ambient>0.4 0.4 0.4 1</ambient>
      <background>0.7 0.7 0.7 1</background>
      <shadows>1</shadows>
    </scene>
    <spherical_coordinates>
      <surface_model>EARTH_WGS84</surface_model>
      <latitude_deg>0</latitude_deg>
      <longitude_deg>0</longitude_deg>
      <elevation>0</elevation>
      <heading_deg>0</heading_deg>
    </spherical_coordinates>
    <model name='Untitled'>
      <pose frame=''>-0.492107 0.043119 0 0 -0 0</pose>
      <link name='Wall_4'>
        <collision name='Wall_4_Collision'>
          <geometry>
            <box>
              <size>5.75 0.15 2.5</size>
            </box>
          </geometry>
          <pose frame=''>0 0 1.25 0 -0 0</pose>
          <max_contacts>10</max_contacts>
          <surface>
            <contact>
              <ode/>
            </contact>
            <bounce/>
            <friction>
              <torsional>
                <ode/>
              </torsional>
              <ode/>
            </friction>
          </surface>
        </collision>
        <visual name='Wall_4_Visual'>
          <pose frame=''>0 0 1.25 0 -0 0</pose>
          <geometry>
            <box>
              <size>5.75 0.15 2.5</size>
            </box>
          </geometry>
          <material>
            <script>
              <uri>file://media/materials/scripts/gazebo.material</uri>
              <name>Gazebo/Wood</name>
            </script>
            <ambient>1 1 1 1</ambient>
          </material>
        </visual>
        <pose frame=''>0.052465 -4.85372 0 0 -0 0</pose>
        <self_collide>0</self_collide>
        <kinematic>0</kinematic>
        <gravity>1</gravity>
      </link>
      <link name='Wall_5'>
        <collision name='Wall_5_Collision'>
          <geometry>
            <box>
              <size>9.75 0.15 2.5</size>
            </box>
          </geometry>
          <pose frame=''>0 0 1.25 0 -0 0</pose>
          <max_contacts>10</max_contacts>
          <surface>
            <contact>
              <ode/>
            </contact>
            <bounce/>
            <friction>
              <torsional>
                <ode/>
              </torsional>
              <ode/>
            </friction>
          </surface>
        </collision>
        <visual name='Wall_5_Visual'>
          <pose frame=''>0 0 1.25 0 -0 0</pose>
          <geometry>
            <box>
              <size>9.75 0.15 2.5</size>
            </box>
          </geometry>
          <material>
            <script>
              <uri>file://media/materials/scripts/gazebo.material</uri>
              <name>Gazebo/Wood</name>
            </script>
            <ambient>1 1 1 1</ambient>
          </material>
        </visual>
        <pose frame=''>2.85247 -0.053721 0 0 -0 1.5708</pose>
        <self_collide>0</self_collide>
        <kinematic>0</kinematic>
        <gravity>1</gravity>
      </link>
      <link name='Wall_6'>
        <collision name='Wall_6_Collision'>
          <geometry>
            <box>
              <size>5.5 0.15 2.5</size>
            </box>
          </geometry>
          <pose frame=''>0 0 1.25 0 -0 0</pose>
          <max_contacts>10</max_contacts>
          <surface>
            <contact>
              <ode/>
            </contact>
            <bounce/>
            <friction>
              <torsional>
                <ode/>
              </torsional>
              <ode/>
            </friction>
          </surface>
        </collision>
        <visual name='Wall_6_Visual'>
          <pose frame=''>0 0 1.25 0 -0 0</pose>
          <geometry>
            <box>
              <size>5.5 0.15 2.5</size>
            </box>
          </geometry>
          <material>
            <script>
              <uri>file://media/materials/scripts/gazebo.material</uri>
              <name>Gazebo/Wood</name>
            </script>
            <ambient>1 1 1 1</ambient>
          </material>
        </visual>
        <pose frame=''>0.177465 4.74628 0 0 -0 3.14159</pose>
        <self_collide>0</self_collide>
        <kinematic>0</kinematic>
        <gravity>1</gravity>
      </link>
      <link name='Wall_8'>
        <collision name='Wall_8_Collision'>
          <geometry>
            <box>
              <size>0.5 0.15 2.5</size>
            </box>
          </geometry>
          <pose frame=''>0 0 1.25 0 -0 0</pose>
          <max_contacts>10</max_contacts>
          <surface>
            <contact>
              <ode/>
            </contact>
            <bounce/>
            <friction>
              <torsional>
                <ode/>
              </torsional>
              <ode/>
            </friction>
          </surface>
        </collision>
        <visual name='Wall_8_Visual'>
          <pose frame=''>0 0 1.25 0 -0 0</pose>
          <geometry>
            <box>
              <size>0.5 0.15 2.5</size>
            </box>
          </geometry>
          <material>
            <script>
              <uri>file://media/materials/scripts/gazebo.material</uri>
              <name>Gazebo/Grey</name>
            </script>
            <ambient>1 1 1 1</ambient>
          </material>
        </visual>
        <pose frame=''>-2.66657 4.79157 0 0 -0 2.87979</pose>
        <self_collide>0</self_collide>
        <kinematic>0</kinematic>
        <gravity>1</gravity>
      </link>
      <link name='Wall_9'>
        <collision name='Wall_9_Collision'>
          <geometry>
            <box>
              <size>9.75 0.15 2.5</size>
            </box>
          </geometry>
          <pose frame=''>0 0 1.25 0 -0 0</pose>
          <max_contacts>10</max_contacts>
          <surface>
            <contact>
              <ode/>
            </contact>
            <bounce/>
            <friction>
              <torsional>
                <ode/>
              </torsional>
              <ode/>
            </friction>
          </surface>
        </collision>
        <visual name='Wall_9_Visual'>
          <pose frame=''>0 0 1.25 0 -0 0</pose>
          <geometry>
            <box>
              <size>9.75 0.15 2.5</size>
            </box>
          </geometry>
          <material>
            <script>
              <uri>file://media/materials/scripts/gazebo.material</uri>
              <name>Gazebo/Wood</name>
            </script>
            <ambient>1 1 1 1</ambient>
          </material>
        </visual>
        <pose frame=''>-2.83561 0.036866 0 0 0 -1.5708</pose>
        <self_collide>0</self_collide>
        <kinematic>0</kinematic>
        <gravity>1</gravity>
      </link>
      <static>1</static>
    </model>
    <state world_name='default'>
      <sim_time>7107 803000000</sim_time>
      <real_time>211 381694758</real_time>
      <wall_time>1591238718 104982836</wall_time>
      <iterations>130954</iterations>
      <model name='Untitled'>
        <pose frame=''>-0.487456 0.28794 0 0 -0 0</pose>
        <scale>1 1 1</scale>
        <link name='Wall_4'>
          <pose frame=''>-0.434991 -4.56578 0 0 -0 0</pose>
          <velocity>0 0 0 0 -0 0</velocity>
          <acceleration>0 0 0 0 -0 0</acceleration>
          <wrench>0 0 0 0 -0 0</wrench>
        </link>
        <link name='Wall_5'>
          <pose frame=''>2.36502 0.234226 0 0 -0 1.5708</pose>
          <velocity>0 0 0 0 -0 0</velocity>
          <acceleration>0 0 0 0 -0 0</acceleration>
          <wrench>0 0 0 0 -0 0</wrench>
        </link>
        <link name='Wall_6'>
          <pose frame=''>-0.309991 5.03422 0 0 -0 3.14159</pose>
          <velocity>0 0 0 0 -0 0</velocity>
          <acceleration>0 0 0 0 -0 0</acceleration>
          <wrench>0 0 0 0 -0 0</wrench>
        </link>
        <link name='Wall_8'>
          <pose frame=''>-3.15402 5.07951 0 0 -0 2.87979</pose>
          <velocity>0 0 0 0 -0 0</velocity>
          <acceleration>0 0 0 0 -0 0</acceleration>
          <wrench>0 0 0 0 -0 0</wrench>
        </link>
        <link name='Wall_9'>
          <pose frame=''>-3.32307 0.324813 0 0 0 -1.5708</pose>
          <velocity>0 0 0 0 -0 0</velocity>
          <acceleration>0 0 0 0 -0 0</acceleration>
          <wrench>0 0 0 0 -0 0</wrench>
        </link>
      </model>
      <model name='beer'>
        <pose frame=''>-0.369102 2.36185 0.469896 -3e-06 -1.8e-05 -0.530269</pose>
        <scale>1 1 1</scale>
        <link name='link'>
          <pose frame=''>-0.369104 2.36185 0.584896 -3e-06 -1.8e-05 -0.530269</pose>
          <velocity>0 0 0 0 -0 0</velocity>
          <acceleration>2.29719 -0.643195 -0.713234 -0.310151 1.06134 1.2686</acceleration>
          <wrench>0.895903 -0.250846 -0.278161 0 -0 0</wrench>
        </link>
      </model>
      <model name='coca_cola'>
        <pose frame=''>-0.560432 2.63547 0.415222 1.5e-05 -5.6e-05 -0.014109</pose>
        <scale>1 1 1</scale>
        <link name='link'>
          <pose frame=''>-0.560438 2.63547 0.530222 1.5e-05 -5.6e-05 -0.014109</pose>
          <velocity>0 0 0 0 -0 0</velocity>
          <acceleration>0.400889 -0.013895 -8.37789 -0.0356 0.491243 -0.543623</acceleration>
          <wrench>0.156347 -0.005419 -3.26738 0 -0 0</wrench>
        </link>
      </model>
      <model name='coke_can'>
        <pose frame=''>-0.452899 2.51264 0.467329 -0.011202 0.004018 0.671686</pose>
        <scale>1 1 1</scale>
        <link name='link'>
          <pose frame=''>-0.452899 2.51264 0.467329 -0.011202 0.004018 0.671686</pose>
          <velocity>0 0 0 0 -0 0</velocity>
          <acceleration>0.053514 -0.02507 19.5966 0.509194 1.17156 0.847991</acceleration>
          <wrench>0.020871 -0.009777 7.64267 0 -0 0</wrench>
        </link>
      </model>
      <model name='cup_paper_1'>
        <pose frame=''>-0.66625 2.39577 0.474823 0 -0 0</pose>
        <scale>1 1 1</scale>
        <link name='link_2'>
          <pose frame=''>-0.724986 2.33924 0.474823 0 -0 0</pose>
          <velocity>0 0 0 0 -0 0</velocity>
          <acceleration>0 0 0 0 -0 0</acceleration>
          <wrench>0 0 0 0 -0 0</wrench>
        </link>
      </model>
      <model name='fetch'>
        <pose frame=''>-0.500155 0.998505 0.001208 -0.000198 -0.005645 1.53232</pose>
        <scale>1 1 1</scale>
        <link name='base_link'>
          <pose frame=''>-0.500155 0.998505 0.001208 -0.000198 -0.005645 1.53232</pose>
          <velocity>-1.2e-05 -4.3e-05 4.8e-05 5.8e-05 -0.000185 4.7e-05</velocity>
          <acceleration>-0.0455 0.059004 0.000574 0.106178 0.050543 0.317704</acceleration>
          <wrench>-3.7955 4.92194 0.047885 0 -0 0</wrench>
        </link>
        <link name='bellows_link'>
          <pose frame=''>-0.503651 0.909607 0.371504 -0.000198 -0.005645 1.53232</pose>
          <velocity>-7.7e-05 -6.7e-05 0.000328 5.3e-05 -0.000189 5.4e-05</velocity>
          <acceleration>-0.019772 0.052351 0.020178 2.43229 -0.208426 0.331414</acceleration>
          <wrench>-0.003349 0.008867 0.003418 0 -0 0</wrench>
        </link>
        <link name='elbow_flex_link'>
          <pose frame=''>-0.668567 1.0791 0.440731 -3.10219 0.018397 -0.091492</pose>
          <velocity>5.7e-05 0.000199 2.8e-05 0.000339 0.001057 -0.000694</velocity>
          <acceleration>-0.185337 0.023732 0.141986 1.04856 0.893181 0.894657</acceleration>
          <wrench>-0.394748 0.050547 0.302416 0 -0 0</wrench>
        </link>
        <link name='forearm_roll_link'>
          <pose frame=''>-0.472424 1.0611 0.437107 -3.10218 0.018397 -0.091492</pose>
          <velocity>4.1e-05 6.3e-05 -0.000185 0.000848 0.001009 -0.000709</velocity>
          <acceleration>-0.189303 0.087312 0.331314 -1.6954 -0.833488 2.93578</acceleration>
          <wrench>-0.313543 0.144615 0.548755 0 -0 0</wrench>
        </link>
        <link name='head_pan_link'>
          <pose frame=''>-0.50186 0.959258 0.981433 -0.000406 -0.005634 1.56922</pose>
          <velocity>-0.000193 -0.0001 6.3e-05 5.7e-05 -0.00018 -0.00116</velocity>
          <acceleration>0.043212 0.002968 -0.000827 -2.9088 0.337697 0.60006</acceleration>
          <wrench>0.097469 0.006694 -0.001866 0 -0 0</wrench>
        </link>
        <link name='head_tilt_link'>
          <pose frame=''>-0.501659 1.10146 1.04023 -0.000418 0.245727 1.56911</pose>
          <velocity>-3.9e-05 -0.000104 7.1e-05 0.007225 -0.000192 -0.001157</velocity>
          <acceleration>0.014026 0.051977 -0.050718 2.61381 1.16024 2.63787</acceleration>
          <wrench>0.012746 0.047232 -0.046087 0 -0 0</wrench>
        </link>
        <link name='l_gripper_finger_link'>
          <pose frame=''>-0.36503 1.10487 0.741344 -0.508494 -1.48979 -2.72672</pose>
          <velocity>0.015324 0.167158 0.006316 0.000186 -0.000427 -4.7e-05</velocity>
          <acceleration>0 0 0 0 -0 0</acceleration>
          <wrench>2.45319 26.6683 1.08628 0 -0 0</wrench>
        </link>
        <link name='l_wheel_link'>
          <pose frame=''>-0.68737 1.00669 0.056502 -0.00021 0.082449 1.5323</pose>
          <velocity>-2.1e-05 -5.9e-05 1.4e-05 0.001005 -0.000347 -2e-06</velocity>
          <acceleration>-0.046969 -0.00129 0.02197 0.034678 -0.867083 0.302137</acceleration>
          <wrench>-0.204512 -0.005615 0.095661 0 -0 0</wrench>
        </link>
        <link name='r_gripper_finger_link'>
          <pose frame=''>-0.377072 0.97466 0.736188 -0.508476 -1.48979 -2.72673</pose>
          <velocity>-0.015462 -0.166728 -0.006867 -0.000732 0.000244 0.000226</velocity>
          <acceleration>-31.022 -333.58 -12.8285 1.98116 -0 -2.42399</acceleration>
          <wrench>-2.47556 -26.6197 -1.02371 0 -0 0</wrench>
        </link>
        <link name='r_wheel_link'>
          <pose frame=''>-0.312887 0.992276 0.056576 -0.000213 -0.141727 1.53235</pose>
          <velocity>-2e-05 -3.8e-05 8.3e-05 0.000426 -0.000327 6e-05</velocity>
          <acceleration>-0.042283 0.124076 -0.017903 -1.85367 -0.804249 0.303209</acceleration>
          <wrench>-0.184109 0.54025 -0.077951 0 -0 0</wrench>
        </link>
        <link name='shoulder_lift_link'>
          <pose frame=''>-0.611364 1.06008 0.787531 -0.032204 1.39869 2.82059</pose>
          <velocity>-0.000108 8.5e-05 4.9e-05 5e-05 -0.000381 -0.001553</velocity>
          <acceleration>-0.085615 -0.044576 0.025005 -0.178144 -0.472893 -2.17893</acceleration>
          <wrench>-0.227865 -0.118639 0.066552 0 -0 0</wrench>
        </link>
        <link name='shoulder_pan_link'>
          <pose frame=''>-0.4992 1.02704 0.72739 -0.00552 -0.001209 2.85233</pose>
          <velocity>-0.000151 -9.3e-05 6.6e-05 3.6e-05 -0.000154 -0.001565</velocity>
          <acceleration>-0.01733 -0.040357 0.009998 0.449581 1.55352 -1.35997</acceleration>
          <wrench>-0.044341 -0.103261 0.025582 0 -0 0</wrench>
        </link>
        <link name='torso_lift_link'>
          <pose frame=''>-0.503653 0.909569 0.378141 -0.000198 -0.005645 1.53232</pose>
          <velocity>-7.8e-05 -6.6e-05 6e-05 5.7e-05 -0.000185 4.9e-05</velocity>
          <acceleration>0.032868 0.027355 -0.007196 -0.015704 0.164249 0.344714</acceleration>
          <wrench>0.359875 0.299513 -0.078789 0 -0 0</wrench>
        </link>
        <link name='upperarm_roll_link'>
          <pose frame=''>-0.646953 1.07191 0.571766 -0.232088 1.39869 2.8206</pose>
          <velocity>-5e-06 0.000156 3.6e-05 0.000197 -0.000434 -0.000751</velocity>
          <acceleration>-0.185563 -0.024821 0.042046 1.85388 0.27501 2.84803</acceleration>
          <wrench>-0.432567 -0.05786 0.098014 0 -0 0</wrench>
        </link>
        <link name='wrist_flex_link'>
          <pose frame=''>-0.348466 1.04973 0.434817 -0.508439 -1.48978 -2.72677</pose>
          <velocity>3e-05 -2.3e-05 -0.000319 0.000703 -0.000588 -0.000764</velocity>
          <acceleration>-0.18028 -0.071957 0.285672 -0.307476 -0.439829 2.47727</acceleration>
          <wrench>-0.310983 -0.124125 0.492785 0 -0 0</wrench>
        </link>
        <link name='wrist_roll_link'>
          <pose frame=''>-0.358723 1.04521 0.572863 -0.508446 -1.48978 -2.72677</pose>
          <velocity>-5.9e-05 -0.000109 -0.000329 0.000652 -0.000611 -9.7e-05</velocity>
          <acceleration>-0.183243 -0.29595 0.280124 2.3575 1.07036 0.456434</acceleration>
          <wrench>-0.302883 -0.489176 0.463017 0 -0 0</wrench>
        </link>
      </model>
      <model name='ground_plane'>
        <pose frame=''>0 0 0 0 -0 0</pose>
        <scale>1 1 1</scale>
        <link name='link'>
          <pose frame=''>0 0 0 0 -0 0</pose>
          <velocity>0 0 0 0 -0 0</velocity>
          <acceleration>0 0 0 0 -0 0</acceleration>
          <wrench>0 0 0 0 -0 0</wrench>
        </link>
      </model>
      <model name='side_table_set_2'>
        <pose frame=''>-0.5 2.5 -0.102284 0 -0 0</pose>
        <scale>1 1 1</scale>
        <link name='link_25'>
          <pose frame=''>0.394224 1.70337 -0.131288 0 -0 0</pose>
          <velocity>0 0 0 0 -0 0</velocity>
          <acceleration>0 0 0 0 -0 0</acceleration>
          <wrench>0 0 0 0 -0 0</wrench>
        </link>
      </model>
      <light name='sun'>
        <pose frame=''>0 0 10 0 -0 0</pose>
      </light>
    </state>
    <gui fullscreen='0'>
      <camera name='user_camera'>
        <pose frame=''>-0.70851 0.361083 2.4825 0 0.933798 1.06399</pose>
        <view_controller>orbit</view_controller>
        <projection_type>perspective</projection_type>
      </camera>
    </gui>
    <model name='side_table_set_2'>
      <link name='link_25'>
        <pose frame=''>0.894224 -0.796632 -0.029004 0 -0 0</pose>
        <visual name='visual'>
          <pose frame=''>0 0 0 0 -0 0</pose>
          <geometry>
            <mesh>
              <uri>model://side_table_set_2/meshes/table_small_full.dae</uri>
              <scale>1 1 1</scale>
            </mesh>
          </geometry>
          <material>
            <lighting>1</lighting>
            <ambient>0.6 0.6 0.6 1</ambient>
            <diffuse>0.7 0.7 0.7 1</diffuse>
            <specular>0.01 0.01 0.01 1</specular>
            <emissive>0 0 0 1</emissive>
          </material>
          <cast_shadows>1</cast_shadows>
          <transparency>0</transparency>
        </visual>
        <collision name='collision'>
          <laser_retro>0</laser_retro>
          <max_contacts>10</max_contacts>
          <pose frame=''>0 0 0 0 -0 0</pose>
          <geometry>
            <mesh>
              <uri>model://side_table_set_2/meshes/table_small_full.dae</uri>
              <scale>1 1 1</scale>
            </mesh>
          </geometry>
          <surface>
            <contact>
              <ode/>
            </contact>
            <bounce/>
            <friction>
              <torsional>
                <ode/>
              </torsional>
              <ode/>
            </friction>
          </surface>
        </collision>
        <self_collide>0</self_collide>
        <kinematic>0</kinematic>
        <gravity>1</gravity>
      </link>
      <static>1</static>
      <allow_auto_disable>1</allow_auto_disable>
      <pose frame=''>-1.22408 2.1314 0 0 -0 0</pose>
    </model>
    <model name='coke_can'>
      <link name='link'>
        <inertial>
          <mass>0.39</mass>
          <inertia>
            <ixx>0.00055575</ixx>
            <ixy>0</ixy>
            <ixz>0</ixz>
            <iyy>0.00055575</iyy>
            <iyz>0</iyz>
            <izz>0.0001755</izz>
          </inertia>
        </inertial>
        <collision name='collision'>
          <pose frame=''>0.003937 0.004724 -0.18 0 -0 0</pose>
          <geometry>
            <mesh>
              <uri>model://coke_can/meshes/coke_can.dae</uri>
              <scale>1 1 1</scale>
            </mesh>
          </geometry>
          <max_contacts>10</max_contacts>
          <surface>
            <contact>
              <ode/>
            </contact>
            <bounce/>
            <friction>
              <torsional>
                <ode/>
              </torsional>
              <ode/>
            </friction>
          </surface>
        </collision>
        <visual name='visual'>
          <pose frame=''>0.003937 0.004724 -0.18 0 -0 0</pose>
          <geometry>
            <mesh>
              <uri>model://coke_can/meshes/coke_can.dae</uri>
              <scale>1 1 1</scale>
            </mesh>
          </geometry>
        </visual>
        <self_collide>0</self_collide>
        <kinematic>0</kinematic>
        <gravity>1</gravity>
      </link>
      <pose frame=''>-0.90179 3.02851 0 0 -0 0</pose>
    </model>
    <model name='beer'>
      <link name='link'>
        <pose frame=''>0 0 0.115 0 -0 0</pose>
        <inertial>
          <mass>0.39</mass>
          <inertia>
            <ixx>0.00058</ixx>
            <ixy>0</ixy>
            <ixz>0</ixz>
            <iyy>0.00058</iyy>
            <iyz>0</iyz>
            <izz>0.00019</izz>
          </inertia>
        </inertial>
        <collision name='collision'>
          <geometry>
            <cylinder>
              <radius>0.055</radius>
              <length>0.23</length>
            </cylinder>
          </geometry>
          <max_contacts>10</max_contacts>
          <surface>
            <contact>
              <ode/>
            </contact>
            <bounce/>
            <friction>
              <torsional>
                <ode/>
              </torsional>
              <ode/>
            </friction>
          </surface>
        </collision>
        <visual name='visual'>
          <geometry>
            <cylinder>
              <radius>0.055</radius>
              <length>0.23</length>
            </cylinder>
          </geometry>
          <material>
            <script>
              <uri>model://beer/materials/scripts</uri>
              <uri>model://beer/materials/textures</uri>
              <name>Beer/Diffuse</name>
            </script>
          </material>
        </visual>
        <self_collide>0</self_collide>
        <kinematic>0</kinematic>
        <gravity>1</gravity>
      </link>
      <pose frame=''>-0.798889 2.85407 0 0 -0 0</pose>
    </model>
    <model name='coca_cola'>
      <link name='link'>
        <pose frame=''>0 0 0.115 0 -0 0</pose>
        <inertial>
          <mass>0.39</mass>
          <inertia>
            <ixx>0.00058</ixx>
            <ixy>0</ixy>
            <ixz>0</ixz>
            <iyy>0.00058</iyy>
            <iyz>0</iyz>
            <izz>0.00019</izz>
          </inertia>
        </inertial>
        <collision name='collision'>
          <geometry>
            <cylinder>
              <radius>0.0301625</radius>
              <length>0.12065</length>
            </cylinder>
          </geometry>
          <max_contacts>10</max_contacts>
          <surface>
            <contact>
              <ode/>
            </contact>
            <bounce/>
            <friction>
              <torsional>
                <ode/>
              </torsional>
              <ode/>
            </friction>
          </surface>
        </collision>
        <visual name='bodyMesh'>
          <geometry>
            <mesh>
              <uri>model://coca_cola/meshes/coke.dae</uri>
              <scale>1 1 1</scale>
            </mesh>
          </geometry>
        </visual>
        <self_collide>0</self_collide>
        <kinematic>0</kinematic>
        <gravity>1</gravity>
      </link>
      <pose frame=''>-1.44278 2.95742 0 0 -0 0</pose>
    </model>
    <model name='cup_paper_1'>
      <link name='link_2'>
        <pose frame=''>-0.058736 -0.056528 -0 0 -0 0</pose>
        <visual name='visual'>
          <pose frame=''>0 0 0 0 -0 0</pose>
          <geometry>
            <mesh>
              <uri>model://cup_paper/meshes/base.dae</uri>
              <scale>1 1 1</scale>
            </mesh>
          </geometry>
          <material>
            <lighting>1</lighting>
            <ambient>1 1 1 1</ambient>
            <diffuse>1 1 1 1</diffuse>
            <specular>0.01 0.01 0.01 1</specular>
            <emissive>0 0 0 1</emissive>
          </material>
          <cast_shadows>1</cast_shadows>
          <transparency>0</transparency>
        </visual>
        <collision name='collision'>
          <laser_retro>0</laser_retro>
          <max_contacts>10</max_contacts>
          <pose frame=''>0 0 0 0 -0 0</pose>
          <geometry>
            <mesh>
              <uri>model://cup_paper/meshes/base.dae</uri>
              <scale>1 1 1</scale>
            </mesh>
          </geometry>
          <surface>
            <contact>
              <ode/>
            </contact>
            <bounce/>
            <friction>
              <torsional>
                <ode/>
              </torsional>
              <ode/>
            </friction>
          </surface>
        </collision>
        <gravity>0</gravity>
        <self_collide>0</self_collide>
        <inertial>
          <inertia>
            <ixx>1</ixx>
            <ixy>0</ixy>
            <ixz>0</ixz>
            <iyy>1</iyy>
            <iyz>0</iyz>
            <izz>1</izz>
          </inertia>
          <mass>1</mass>
        </inertial>
        <kinematic>0</kinematic>
      </link>
      <allow_auto_disable>1</allow_auto_disable>
      <pose frame=''>-1.23205 2.68828 0 0 -0 0</pose>
    </model>
    <model name='fetch'>
      <link name='base_link'>
        <pose frame=''>0 0 0 0 -0 0</pose>
        <inertial>
          <pose frame=''>-0.028329 0.000913 0.103558 0 -0 0</pose>
          <mass>83.4172</mass>
          <inertia>
            <ixx>6.20776</ixx>
            <ixy>0.0213393</ixy>
            <ixz>1.10946</ixz>
            <iyy>6.49062</iyy>
            <iyz>-0.0326202</iyz>
            <izz>1.3596</izz>
          </inertia>
        </inertial>
        <collision name='base_link_collision'>
          <pose frame=''>0 0 0 0 -0 0</pose>
          <geometry>
            <mesh>
              <scale>1 1 1</scale>
              <uri>/opt/ros/kinetic/share/fetch_description/meshes/base_link_collision.STL</uri>
            </mesh>
          </geometry>
          <surface>
            <contact>
              <ode>
                <kp>1e+08</kp>
                <kd>10</kd>
                <max_vel>10</max_vel>
                <min_depth>0.0005</min_depth>
              </ode>
            </contact>
            <friction>
              <ode>
                <mu>0.1</mu>
                <mu2>0.1</mu2>
                <fdir1>1 0 0</fdir1>
              </ode>
              <torsional>
                <ode/>
              </torsional>
            </friction>
            <bounce/>
          </surface>
          <max_contacts>10</max_contacts>
        </collision>
        <collision name='base_link_fixed_joint_lump__estop_link_collision_1'>
          <pose frame=''>-0.12465 0.23892 0.31127 1.5708 -0 0</pose>
          <geometry>
            <mesh>
              <scale>1 1 1</scale>
              <uri>/opt/ros/kinetic/share/fetch_description/meshes/estop_link.STL</uri>
            </mesh>
          </geometry>
          <surface>
            <contact>
              <ode/>
            </contact>
            <friction>
              <ode/>
              <torsional>
                <ode/>
              </torsional>
            </friction>
            <bounce/>
          </surface>
          <max_contacts>10</max_contacts>
        </collision>
        <collision name='base_link_fixed_joint_lump__laser_link_collision_2'>
          <pose frame=''>0.235 0 0.2878 -3.14159 -0 0</pose>
          <geometry>
            <mesh>
              <scale>1 1 1</scale>
              <uri>/opt/ros/kinetic/share/fetch_description/meshes/laser_link.STL</uri>
            </mesh>
          </geometry>
          <surface>
            <contact>
              <ode/>
            </contact>
            <friction>
              <ode/>
              <torsional>
                <ode/>
              </torsional>
            </friction>
            <bounce/>
          </surface>
          <max_contacts>10</max_contacts>
        </collision>
        <collision name='base_link_fixed_joint_lump__torso_fixed_link_collision_3'>
          <pose frame=''>-0.086875 0 0.377425 0 -0 0</pose>
          <geometry>
            <mesh>
              <scale>1 1 1</scale>
              <uri>/opt/ros/kinetic/share/fetch_description/meshes/torso_fixed_link.STL</uri>
            </mesh>
          </geometry>
          <max_contacts>10</max_contacts>
          <surface>
            <contact>
              <ode/>
            </contact>
            <bounce/>
            <friction>
              <torsional>
                <ode/>
              </torsional>
              <ode/>
            </friction>
          </surface>
        </collision>
        <visual name='base_link_visual'>
          <pose frame=''>0 0 0 0 -0 0</pose>
          <geometry>
            <mesh>
              <scale>1 1 1</scale>
              <uri>/opt/ros/kinetic/share/fetch_description/meshes/base_link.dae</uri>
            </mesh>
          </geometry>
          <material>
            <script>
              <uri>__default__</uri>
              <name>__default__</name>
            </script>
          </material>
        </visual>
        <visual name='base_link_fixed_joint_lump__estop_link_visual_1'>
          <pose frame=''>-0.12465 0.23892 0.31127 1.5708 -0 0</pose>
          <geometry>
            <mesh>
              <scale>1 1 1</scale>
              <uri>/opt/ros/kinetic/share/fetch_description/meshes/estop_link.STL</uri>
            </mesh>
          </geometry>
          <material>
            <script>
              <name>Gazebo/Red</name>
              <uri>file://media/materials/scripts/gazebo.material</uri>
            </script>
          </material>
        </visual>
        <visual name='base_link_fixed_joint_lump__laser_link_visual_2'>
          <pose frame=''>0.235 0 0.2878 -3.14159 -0 0</pose>
          <geometry>
            <mesh>
              <scale>1 1 1</scale>
              <uri>/opt/ros/kinetic/share/fetch_description/meshes/laser_link.STL</uri>
            </mesh>
          </geometry>
          <material>
            <script>
              <uri>__default__</uri>
              <name>__default__</name>
            </script>
          </material>
        </visual>
        <visual name='base_link_fixed_joint_lump__torso_fixed_link_visual_3'>
          <pose frame=''>-0.086875 0 0.377425 0 -0 0</pose>
          <geometry>
            <mesh>
              <scale>1 1 1</scale>
              <uri>/opt/ros/kinetic/share/fetch_description/meshes/torso_fixed_link.dae</uri>
            </mesh>
          </geometry>
        </visual>
        <velocity_decay/>
        <velocity_decay/>
        <gravity>1</gravity>
        <velocity_decay/>
        <self_collide>0</self_collide>
        <sensor name='base_laser' type='ray'>
          <visualize>0</visualize>
          <update_rate>15</update_rate>
          <ray>
            <scan>
              <horizontal>
                <samples>662</samples>
                <resolution>1</resolution>
                <min_angle>-1.91986</min_angle>
                <max_angle>1.91986</max_angle>
              </horizontal>
              <vertical>
                <samples>1</samples>
                <min_angle>0</min_angle>
                <max_angle>0</max_angle>
              </vertical>
            </scan>
            <range>
              <min>0.05</min>
              <max>25</max>
              <resolution>0.01</resolution>
            </range>
            <noise>
              <type>gaussian</type>
              <mean>0</mean>
              <stddev>0</stddev>
            </noise>
          </ray>
          <plugin name='gazebo_ros_base_hokuyo_controller' filename='libgazebo_ros_laser.so'>
            <topicName>/base_scan</topicName>
            <frameName>laser_link</frameName>
            <robotNamespace>/</robotNamespace>
          </plugin>
          <pose frame=''>0.235 0 0.2878 -3.14159 -0 0</pose>
        </sensor>
        <kinematic>0</kinematic>
      </link>
      <link name='l_wheel_link'>
        <pose frame=''>0.001291 0.18738 0.055325 0 -0 0</pose>
        <inertial>
          <pose frame=''>0 0 0 0 -0 0</pose>
          <mass>4.3542</mass>
          <inertia>
            <ixx>0.0045</ixx>
            <ixy>0</ixy>
            <ixz>0</ixz>
            <iyy>0.005</iyy>
            <iyz>0</iyz>
            <izz>0.0045</izz>
          </inertia>
        </inertial>
        <collision name='l_wheel_link_collision'>
          <pose frame=''>0 0 0 0 -0 0</pose>
          <geometry>
            <mesh>
              <scale>1 1 1</scale>
              <uri>/opt/ros/kinetic/share/fetch_description/meshes/l_wheel_link_collision.STL</uri>
            </mesh>
          </geometry>
          <surface>
            <contact>
              <ode>
                <kp>500000</kp>
                <kd>10</kd>
                <max_vel>1</max_vel>
                <min_depth>0.003</min_depth>
              </ode>
            </contact>
            <friction>
              <ode>
                <mu>10</mu>
                <mu2>10</mu2>
                <fdir1>1 0 0</fdir1>
              </ode>
              <torsional>
                <ode/>
              </torsional>
            </friction>
            <bounce/>
          </surface>
          <max_contacts>10</max_contacts>
        </collision>
        <visual name='l_wheel_link_visual'>
          <pose frame=''>0 0 0 0 -0 0</pose>
          <geometry>
            <mesh>
              <scale>1 1 1</scale>
              <uri>/opt/ros/kinetic/share/fetch_description/meshes/l_wheel_link.STL</uri>
            </mesh>
          </geometry>
          <material>
            <script>
              <name>Gazebo/Black</name>
              <uri>file://media/materials/scripts/gazebo.material</uri>
            </script>
          </material>
        </visual>
        <gravity>1</gravity>
        <velocity_decay/>
        <self_collide>0</self_collide>
        <kinematic>0</kinematic>
      </link>
      <joint name='l_wheel_joint' type='revolute'>
        <child>l_wheel_link</child>
        <parent>base_link</parent>
        <axis>
          <xyz>0 1 0</xyz>
          <limit>
            <lower>-1e+16</lower>
            <upper>1e+16</upper>
          </limit>
          <dynamics>
            <spring_reference>0</spring_reference>
            <spring_stiffness>0</spring_stiffness>
          </dynamics>
          <use_parent_model_frame>1</use_parent_model_frame>
        </axis>
        <physics>
          <ode>
            <implicit_spring_damper>1</implicit_spring_damper>
            <cfm_damping>1</cfm_damping>
            <limit>
              <cfm>0</cfm>
              <erp>0.2</erp>
            </limit>
          </ode>
        </physics>
      </joint>
      <link name='r_wheel_link'>
        <pose frame=''>0.001291 -0.18738 0.055325 0 -0 0</pose>
        <inertial>
          <pose frame=''>0 0 0 0 -0 0</pose>
          <mass>4.3542</mass>
          <inertia>
            <ixx>0.0045</ixx>
            <ixy>0</ixy>
            <ixz>0</ixz>
            <iyy>0.005</iyy>
            <iyz>0</iyz>
            <izz>0.0045</izz>
          </inertia>
        </inertial>
        <collision name='r_wheel_link_collision'>
          <pose frame=''>0 0 0 0 -0 0</pose>
          <geometry>
            <mesh>
              <scale>1 1 1</scale>
              <uri>/opt/ros/kinetic/share/fetch_description/meshes/r_wheel_link_collision.STL</uri>
            </mesh>
          </geometry>
          <surface>
            <contact>
              <ode>
                <kp>500000</kp>
                <kd>10</kd>
                <max_vel>1</max_vel>
                <min_depth>0.003</min_depth>
              </ode>
            </contact>
            <friction>
              <ode>
                <mu>10</mu>
                <mu2>10</mu2>
                <fdir1>1 0 0</fdir1>
              </ode>
              <torsional>
                <ode/>
              </torsional>
            </friction>
            <bounce/>
          </surface>
          <max_contacts>10</max_contacts>
        </collision>
        <visual name='r_wheel_link_visual'>
          <pose frame=''>0 0 0 0 -0 0</pose>
          <geometry>
            <mesh>
              <scale>1 1 1</scale>
              <uri>/opt/ros/kinetic/share/fetch_description/meshes/r_wheel_link.STL</uri>
            </mesh>
          </geometry>
          <material>
            <script>
              <name>Gazebo/Black</name>
              <uri>file://media/materials/scripts/gazebo.material</uri>
            </script>
          </material>
        </visual>
        <gravity>1</gravity>
        <velocity_decay/>
        <self_collide>0</self_collide>
        <kinematic>0</kinematic>
      </link>
      <joint name='r_wheel_joint' type='revolute'>
        <child>r_wheel_link</child>
        <parent>base_link</parent>
        <axis>
          <xyz>0 1 0</xyz>
          <limit>
            <lower>-1e+16</lower>
            <upper>1e+16</upper>
          </limit>
          <dynamics>
            <spring_reference>0</spring_reference>
            <spring_stiffness>0</spring_stiffness>
          </dynamics>
          <use_parent_model_frame>1</use_parent_model_frame>
        </axis>
        <physics>
          <ode>
            <implicit_spring_damper>1</implicit_spring_damper>
            <cfm_damping>1</cfm_damping>
            <limit>
              <cfm>0</cfm>
              <erp>0.2</erp>
            </limit>
          </ode>
        </physics>
      </joint>
      <link name='torso_lift_link'>
        <pose frame=''>-0.086875 0 0.37743 0 -0 0</pose>
        <inertial>
          <pose frame=''>-0.000984 -0.000886 0.286874 0 -0 0</pose>
          <mass>10.949</mass>
          <inertia>
            <ixx>0.36931</ixx>
            <ixy>-3.0664e-06</ixy>
            <ixz>-0.0147406</ixz>
            <iyy>0.367812</iyy>
            <iyz>-0.000535712</iyz>
            <izz>0.0971639</izz>
          </inertia>
        </inertial>
        <collision name='torso_lift_link_collision'>
          <pose frame=''>0 0 0 0 -0 0</pose>
          <geometry>
            <mesh>
              <scale>1 1 1</scale>
              <uri>/opt/ros/kinetic/share/fetch_description/meshes/torso_lift_link_collision.STL</uri>
            </mesh>
          </geometry>
          <max_contacts>10</max_contacts>
          <surface>
            <contact>
              <ode/>
            </contact>
            <bounce/>
            <friction>
              <torsional>
                <ode/>
              </torsional>
              <ode/>
            </friction>
          </surface>
        </collision>
        <collision name='torso_lift_link_fixed_joint_lump__bellows_link2_collision_1'>
          <pose frame=''>0 0 0 0 -0 0</pose>
          <geometry>
            <mesh>
              <scale>1 1 1</scale>
              <uri>/opt/ros/kinetic/share/fetch_description/meshes/bellows_link_collision.STL</uri>
            </mesh>
          </geometry>
          <surface>
            <contact>
              <ode/>
            </contact>
            <friction>
              <ode/>
              <torsional>
                <ode/>
              </torsional>
            </friction>
            <bounce/>
          </surface>
          <max_contacts>10</max_contacts>
        </collision>
        <visual name='torso_lift_link_visual'>
          <pose frame=''>0 0 0 0 -0 0</pose>
          <geometry>
            <mesh>
              <scale>1 1 1</scale>
              <uri>/opt/ros/kinetic/share/fetch_description/meshes/torso_lift_link.dae</uri>
            </mesh>
          </geometry>
        </visual>
        <visual name='torso_lift_link_fixed_joint_lump__bellows_link2_visual_1'>
          <pose frame=''>0 0 0 0 -0 0</pose>
          <geometry>
            <mesh>
              <scale>1 1 1</scale>
              <uri>/opt/ros/kinetic/share/fetch_description/meshes/bellows_link.STL</uri>
            </mesh>
          </geometry>
          <material>
            <script>
              <name>Gazebo/Black</name>
              <uri>file://media/materials/scripts/gazebo.material</uri>
            </script>
          </material>
        </visual>
        <gravity>1</gravity>
        <velocity_decay/>
        <self_collide>0</self_collide>
        <kinematic>0</kinematic>
      </link>
      <joint name='torso_lift_joint' type='prismatic'>
        <child>torso_lift_link</child>
        <parent>base_link</parent>
        <axis>
          <xyz>0 0 1</xyz>
          <limit>
            <lower>0</lower>
            <upper>0.38615</upper>
            <effort>450</effort>
            <velocity>0.1</velocity>
          </limit>
          <dynamics>
            <damping>100</damping>
            <friction>0</friction>
            <spring_reference>0</spring_reference>
            <spring_stiffness>0</spring_stiffness>
          </dynamics>
          <use_parent_model_frame>1</use_parent_model_frame>
        </axis>
      </joint>
      <link name='bellows_link'>
        <pose frame=''>-0.086875 0 0.37743 0 -0 0</pose>
        <inertial>
          <pose frame=''>0.019132 -0 -0.134862 0 -0 0</pose>
          <mass>0.169374</mass>
          <inertia>
            <ixx>0.00331159</ixx>
            <ixy>-8.9231e-18</ixy>
            <ixz>-5.38622e-08</ixz>
            <iyy>0.00174447</iyy>
            <iyz>-8.06965e-17</iyz>
            <izz>0.00169418</izz>
          </inertia>
        </inertial>
        <collision name='bellows_link_collision'>
          <pose frame=''>0 0 0 0 -0 0</pose>
          <geometry>
            <mesh>
              <scale>1 1 1</scale>
              <uri>/opt/ros/kinetic/share/fetch_description/meshes/bellows_link_collision.STL</uri>
            </mesh>
          </geometry>
          <surface>
            <contact>
              <ode/>
            </contact>
            <friction>
              <ode/>
              <torsional>
                <ode/>
              </torsional>
            </friction>
            <bounce/>
          </surface>
          <max_contacts>10</max_contacts>
        </collision>
        <visual name='bellows_link_visual'>
          <pose frame=''>0 0 0 0 -0 0</pose>
          <geometry>
            <mesh>
              <scale>1 1 1</scale>
              <uri>/opt/ros/kinetic/share/fetch_description/meshes/bellows_link.STL</uri>
            </mesh>
          </geometry>
          <material>
            <script>
              <name>Gazebo/Black</name>
              <uri>file://media/materials/scripts/gazebo.material</uri>
            </script>
          </material>
        </visual>
        <gravity>1</gravity>
        <velocity_decay/>
        <self_collide>0</self_collide>
        <kinematic>0</kinematic>
      </link>
      <joint name='bellows_joint' type='prismatic'>
        <child>bellows_link</child>
        <parent>torso_lift_link</parent>
        <axis>
          <xyz>0 -0 -1</xyz>
          <limit>
            <lower>0</lower>
            <upper>0.4</upper>
            <effort>5</effort>
            <velocity>0.1</velocity>
          </limit>
          <dynamics>
            <spring_reference>0</spring_reference>
            <spring_stiffness>0</spring_stiffness>
          </dynamics>
          <use_parent_model_frame>1</use_parent_model_frame>
        </axis>
      </joint>
      <link name='head_pan_link'>
        <pose frame=''>-0.03375 0 0.980431 0 -0 0</pose>
        <inertial>
          <pose frame=''>0.0321 0.0161 0.039 0 -0 0</pose>
          <mass>2.2556</mass>
          <inertia>
            <ixx>0.0129</ixx>
            <ixy>0.0002</ixy>
            <ixz>0.0007</ixz>
            <iyy>0.0095</iyy>
            <iyz>-0</iyz>
            <izz>0.0184</izz>
          </inertia>
        </inertial>
        <collision name='head_pan_link_collision'>
          <pose frame=''>0 0 0 0 -0 0</pose>
          <geometry>
            <mesh>
              <scale>1 1 1</scale>
              <uri>/opt/ros/kinetic/share/fetch_description/meshes/head_pan_link_collision.STL</uri>
            </mesh>
          </geometry>
          <max_contacts>10</max_contacts>
          <surface>
            <contact>
              <ode/>
            </contact>
            <bounce/>
            <friction>
              <torsional>
                <ode/>
              </torsional>
              <ode/>
            </friction>
          </surface>
        </collision>
        <visual name='head_pan_link_visual'>
          <pose frame=''>0 0 0 0 -0 0</pose>
          <geometry>
            <mesh>
              <scale>1 1 1</scale>
              <uri>/opt/ros/kinetic/share/fetch_description/meshes/head_pan_link.dae</uri>
            </mesh>
          </geometry>
        </visual>
        <self_collide>0</self_collide>
        <kinematic>0</kinematic>
        <gravity>1</gravity>
      </link>
      <joint name='head_pan_joint' type='revolute'>
        <child>head_pan_link</child>
        <parent>torso_lift_link</parent>
        <axis>
          <xyz>0 0 1</xyz>
          <limit>
            <lower>-1.57</lower>
            <upper>1.57</upper>
            <effort>0.32</effort>
            <velocity>1.57</velocity>
          </limit>
          <dynamics>
            <spring_reference>0</spring_reference>
            <spring_stiffness>0</spring_stiffness>
          </dynamics>
          <use_parent_model_frame>1</use_parent_model_frame>
        </axis>
      </joint>
      <link name='head_tilt_link'>
        <pose frame=''>0.10878 0 1.03843 0 -0 0</pose>
        <inertial>
          <pose frame=''>0.0081 0.0025 0.0113 0 -0 0</pose>
          <mass>0.9087</mass>
          <inertia>
            <ixx>0.0061</ixx>
            <ixy>-0</ixy>
            <ixz>0.0002</ixz>
            <iyy>0.0014</iyy>
            <iyz>-0.0001</iyz>
            <izz>0.0061</izz>
          </inertia>
        </inertial>
        <collision name='head_tilt_link_collision'>
          <pose frame=''>0 0 0 0 -0 0</pose>
          <geometry>
            <mesh>
              <scale>1 1 1</scale>
              <uri>/opt/ros/kinetic/share/fetch_description/meshes/head_tilt_link_collision.STL</uri>
            </mesh>
          </geometry>
          <max_contacts>10</max_contacts>
          <surface>
            <contact>
              <ode/>
            </contact>
            <bounce/>
            <friction>
              <torsional>
                <ode/>
              </torsional>
              <ode/>
            </friction>
          </surface>
        </collision>
        <visual name='head_tilt_link_visual'>
          <pose frame=''>0 0 0 0 -0 0</pose>
          <geometry>
            <mesh>
              <scale>1 1 1</scale>
              <uri>/opt/ros/kinetic/share/fetch_description/meshes/head_tilt_link.dae</uri>
            </mesh>
          </geometry>
        </visual>
        <gravity>1</gravity>
        <velocity_decay/>
        <self_collide>0</self_collide>
        <sensor name='camera' type='depth'>
          <always_on>1</always_on>
          <update_rate>10</update_rate>
          <camera name='__default__'>
            <horizontal_fov>1.0472</horizontal_fov>
            <image>
              <format>B8G8R8</format>
              <width>640</width>
              <height>480</height>
            </image>
            <clip>
              <near>0.05</near>
              <far>2.5</far>
            </clip>
          </camera>
          <plugin name='head_camera_controller' filename='libgazebo_ros_openni_kinect.so'>
            <baseline>0.1</baseline>
            <alwaysOn>true</alwaysOn>
            <updateRate>10.0</updateRate>
            <cameraName>head_camera</cameraName>
            <imageTopicName>/head_camera/rgb/image_raw</imageTopicName>
            <cameraInfoTopicName>/head_camera/rgb/camera_info</cameraInfoTopicName>
            <depthImageTopicName>/head_camera/depth_registered/image_raw</depthImageTopicName>
            <depthImageCameraInfoTopicName>/head_camera/depth_registered/camera_info</depthImageCameraInfoTopicName>
            <pointCloudTopicName>/head_camera/depth_registered/points</pointCloudTopicName>
            <frameName>head_camera_rgb_optical_frame</frameName>
            <pointCloudCutoff>0.1</pointCloudCutoff>
            <pointCloudCutoffMax>3</pointCloudCutoffMax>
            <CxPrime>0</CxPrime>
            <Cx>0</Cx>
            <Cy>0</Cy>
            <focalLength>0</focalLength>
            <hackBaseline>0</hackBaseline>
            <robotNamespace>/</robotNamespace>
          </plugin>
          <pose frame=''>0.055 0.02 0.0225 0 -0 0</pose>
        </sensor>
        <kinematic>0</kinematic>
      </link>
      <joint name='head_tilt_joint' type='revolute'>
        <child>head_tilt_link</child>
        <parent>head_pan_link</parent>
        <axis>
          <xyz>0 1 0</xyz>
          <limit>
            <lower>-0.76</lower>
            <upper>1.45</upper>
            <effort>0.68</effort>
            <velocity>1.57</velocity>
          </limit>
          <dynamics>
            <spring_reference>0</spring_reference>
            <spring_stiffness>0</spring_stiffness>
          </dynamics>
          <use_parent_model_frame>1</use_parent_model_frame>
        </axis>
      </joint>
      <link name='shoulder_pan_link'>
        <pose frame=''>0.03265 0 0.72601 0 -0 0</pose>
        <inertial>
          <pose frame=''>0.0927 -0.0056 0.0564 0 -0 0</pose>
          <mass>2.5587</mass>
          <inertia>
            <ixx>0.0043</ixx>
            <ixy>-0.0001</ixy>
            <ixz>0.001</ixz>
            <iyy>0.0087</iyy>
            <iyz>-0.0001</iyz>
            <izz>0.0087</izz>
          </inertia>
        </inertial>
        <collision name='shoulder_pan_link_collision'>
          <pose frame=''>0 0 0 0 -0 0</pose>
          <geometry>
            <mesh>
              <scale>1 1 1</scale>
              <uri>/opt/ros/kinetic/share/fetch_description/meshes/shoulder_pan_link_collision.STL</uri>
            </mesh>
          </geometry>
          <max_contacts>10</max_contacts>
          <surface>
            <contact>
              <ode/>
            </contact>
            <bounce/>
            <friction>
              <torsional>
                <ode/>
              </torsional>
              <ode/>
            </friction>
          </surface>
        </collision>
        <visual name='shoulder_pan_link_visual'>
          <pose frame=''>0 0 0 0 -0 0</pose>
          <geometry>
            <mesh>
              <scale>1 1 1</scale>
              <uri>/opt/ros/kinetic/share/fetch_description/meshes/shoulder_pan_link.dae</uri>
            </mesh>
          </geometry>
        </visual>
        <self_collide>0</self_collide>
        <kinematic>0</kinematic>
        <gravity>1</gravity>
      </link>
      <joint name='shoulder_pan_joint' type='revolute'>
        <child>shoulder_pan_link</child>
        <parent>torso_lift_link</parent>
        <axis>
          <xyz>0 0 1</xyz>
          <limit>
            <lower>-1.6056</lower>
            <upper>1.6056</upper>
            <effort>33.82</effort>
            <velocity>1.256</velocity>
          </limit>
          <dynamics>
            <damping>1</damping>
            <friction>0</friction>
            <spring_reference>0</spring_reference>
            <spring_stiffness>0</spring_stiffness>
          </dynamics>
          <use_parent_model_frame>1</use_parent_model_frame>
        </axis>
      </joint>
      <link name='shoulder_lift_link'>
        <pose frame=''>0.14965 0 0.78601 0 -0 0</pose>
        <inertial>
          <pose frame=''>0.1432 0.0072 -0.0001 0 -0 0</pose>
          <mass>2.6615</mass>
          <inertia>
            <ixx>0.0028</ixx>
            <ixy>-0.0021</ixy>
            <ixz>-0</ixz>
            <iyy>0.0111</iyy>
            <iyz>-0</iyz>
            <izz>0.0112</izz>
          </inertia>
        </inertial>
        <collision name='shoulder_lift_link_collision'>
          <pose frame=''>0 0 0 0 -0 0</pose>
          <geometry>
            <mesh>
              <scale>1 1 1</scale>
              <uri>/opt/ros/kinetic/share/fetch_description/meshes/shoulder_lift_link_collision.STL</uri>
            </mesh>
          </geometry>
          <max_contacts>10</max_contacts>
          <surface>
            <contact>
              <ode/>
            </contact>
            <bounce/>
            <friction>
              <torsional>
                <ode/>
              </torsional>
              <ode/>
            </friction>
          </surface>
        </collision>
        <visual name='shoulder_lift_link_visual'>
          <pose frame=''>0 0 0 0 -0 0</pose>
          <geometry>
            <mesh>
              <scale>1 1 1</scale>
              <uri>/opt/ros/kinetic/share/fetch_description/meshes/shoulder_lift_link.dae</uri>
            </mesh>
          </geometry>
        </visual>
        <self_collide>0</self_collide>
        <kinematic>0</kinematic>
        <gravity>1</gravity>
      </link>
      <joint name='shoulder_lift_joint' type='revolute'>
        <child>shoulder_lift_link</child>
        <parent>shoulder_pan_link</parent>
        <axis>
          <xyz>0 1 0</xyz>
          <limit>
            <lower>-1.221</lower>
            <upper>1.518</upper>
            <effort>131.76</effort>
            <velocity>1.454</velocity>
          </limit>
          <dynamics>
            <damping>1</damping>
            <friction>0</friction>
            <spring_reference>0</spring_reference>
            <spring_stiffness>0</spring_stiffness>
          </dynamics>
          <use_parent_model_frame>1</use_parent_model_frame>
        </axis>
      </joint>
      <link name='upperarm_roll_link'>
        <pose frame=''>0.36865 0 0.78601 0 -0 0</pose>
        <inertial>
          <pose frame=''>0.1165 0.0014 0 0 -0 0</pose>
          <mass>2.3311</mass>
          <inertia>
            <ixx>0.0019</ixx>
            <ixy>-0.0001</ixy>
            <ixz>0</ixz>
            <iyy>0.0045</iyy>
            <iyz>0</iyz>
            <izz>0.0047</izz>
          </inertia>
        </inertial>
        <collision name='upperarm_roll_link_collision'>
          <pose frame=''>0 0 0 0 -0 0</pose>
          <geometry>
            <mesh>
              <scale>1 1 1</scale>
              <uri>/opt/ros/kinetic/share/fetch_description/meshes/upperarm_roll_link_collision.STL</uri>
            </mesh>
          </geometry>
          <max_contacts>10</max_contacts>
          <surface>
            <contact>
              <ode/>
            </contact>
            <bounce/>
            <friction>
              <torsional>
                <ode/>
              </torsional>
              <ode/>
            </friction>
          </surface>
        </collision>
        <visual name='upperarm_roll_link_visual'>
          <pose frame=''>0 0 0 0 -0 0</pose>
          <geometry>
            <mesh>
              <scale>1 1 1</scale>
              <uri>/opt/ros/kinetic/share/fetch_description/meshes/upperarm_roll_link.dae</uri>
            </mesh>
          </geometry>
        </visual>
        <self_collide>0</self_collide>
        <kinematic>0</kinematic>
        <gravity>1</gravity>
      </link>
      <joint name='upperarm_roll_joint' type='revolute'>
        <child>upperarm_roll_link</child>
        <parent>shoulder_lift_link</parent>
        <axis>
          <xyz>1 0 0</xyz>
          <limit>
            <lower>-1e+16</lower>
            <upper>1e+16</upper>
          </limit>
          <dynamics>
            <damping>5</damping>
            <friction>0</friction>
            <spring_reference>0</spring_reference>
            <spring_stiffness>0</spring_stiffness>
          </dynamics>
          <use_parent_model_frame>1</use_parent_model_frame>
        </axis>
      </joint>
      <link name='elbow_flex_link'>
        <pose frame=''>0.50165 0 0.78601 0 -0 0</pose>
        <inertial>
          <pose frame=''>0.1279 0.0073 0 0 -0 0</pose>
          <mass>2.1299</mass>
          <inertia>
            <ixx>0.0024</ixx>
            <ixy>-0.0016</ixy>
            <ixz>0</ixz>
            <iyy>0.0082</iyy>
            <iyz>-0</iyz>
            <izz>0.0084</izz>
          </inertia>
        </inertial>
        <collision name='elbow_flex_link_collision'>
          <pose frame=''>0 0 0 0 -0 0</pose>
          <geometry>
            <mesh>
              <scale>1 1 1</scale>
              <uri>/opt/ros/kinetic/share/fetch_description/meshes/elbow_flex_link_collision.STL</uri>
            </mesh>
          </geometry>
          <max_contacts>10</max_contacts>
          <surface>
            <contact>
              <ode/>
            </contact>
            <bounce/>
            <friction>
              <torsional>
                <ode/>
              </torsional>
              <ode/>
            </friction>
          </surface>
        </collision>
        <visual name='elbow_flex_link_visual'>
          <pose frame=''>0 0 0 0 -0 0</pose>
          <geometry>
            <mesh>
              <scale>1 1 1</scale>
              <uri>/opt/ros/kinetic/share/fetch_description/meshes/elbow_flex_link.dae</uri>
            </mesh>
          </geometry>
        </visual>
        <self_collide>0</self_collide>
        <kinematic>0</kinematic>
        <gravity>1</gravity>
      </link>
      <joint name='elbow_flex_joint' type='revolute'>
        <child>elbow_flex_link</child>
        <parent>upperarm_roll_link</parent>
        <axis>
          <xyz>0 1 0</xyz>
          <limit>
            <lower>-2.251</lower>
            <upper>2.251</upper>
            <effort>66.18</effort>
            <velocity>1.521</velocity>
          </limit>
          <dynamics>
            <damping>1</damping>
            <friction>0</friction>
            <spring_reference>0</spring_reference>
            <spring_stiffness>0</spring_stiffness>
          </dynamics>
          <use_parent_model_frame>1</use_parent_model_frame>
        </axis>
      </joint>
      <link name='forearm_roll_link'>
        <pose frame=''>0.69865 0 0.78601 0 -0 0</pose>
        <inertial>
          <pose frame=''>0.1097 -0.0266 0 0 -0 0</pose>
          <mass>1.6563</mass>
          <inertia>
            <ixx>0.0016</ixx>
            <ixy>-0.0003</ixy>
            <ixz>0</ixz>
            <iyy>0.003</iyy>
            <iyz>-0</iyz>
            <izz>0.0035</izz>
          </inertia>
        </inertial>
        <collision name='forearm_roll_link_collision'>
          <pose frame=''>0 0 0 0 -0 0</pose>
          <geometry>
            <mesh>
              <scale>1 1 1</scale>
              <uri>/opt/ros/kinetic/share/fetch_description/meshes/forearm_roll_link_collision.STL</uri>
            </mesh>
          </geometry>
          <max_contacts>10</max_contacts>
          <surface>
            <contact>
              <ode/>
            </contact>
            <bounce/>
            <friction>
              <torsional>
                <ode/>
              </torsional>
              <ode/>
            </friction>
          </surface>
        </collision>
        <visual name='forearm_roll_link_visual'>
          <pose frame=''>0 0 0 0 -0 0</pose>
          <geometry>
            <mesh>
              <scale>1 1 1</scale>
              <uri>/opt/ros/kinetic/share/fetch_description/meshes/forearm_roll_link.dae</uri>
            </mesh>
          </geometry>
        </visual>
        <self_collide>0</self_collide>
        <kinematic>0</kinematic>
        <gravity>1</gravity>
      </link>
      <joint name='forearm_roll_joint' type='revolute'>
        <child>forearm_roll_link</child>
        <parent>elbow_flex_link</parent>
        <axis>
          <xyz>1 0 0</xyz>
          <limit>
            <lower>-1e+16</lower>
            <upper>1e+16</upper>
          </limit>
          <dynamics>
            <damping>5</damping>
            <friction>0</friction>
            <spring_reference>0</spring_reference>
            <spring_stiffness>0</spring_stiffness>
          </dynamics>
          <use_parent_model_frame>1</use_parent_model_frame>
        </axis>
        <physics>
          <ode>
            <implicit_spring_damper>1</implicit_spring_damper>
            <cfm_damping>1</cfm_damping>
            <limit>
              <cfm>0</cfm>
              <erp>0.2</erp>
            </limit>
          </ode>
        </physics>
      </joint>
      <link name='wrist_flex_link'>
        <pose frame=''>0.82315 0 0.78601 0 -0 0</pose>
        <inertial>
          <pose frame=''>0.0882 0.0009 -0.0001 0 -0 0</pose>
          <mass>1.725</mass>
          <inertia>
            <ixx>0.0018</ixx>
            <ixy>-0.0001</ixy>
            <ixz>-0</ixz>
            <iyy>0.0042</iyy>
            <iyz>0</iyz>
            <izz>0.0042</izz>
          </inertia>
        </inertial>
        <collision name='wrist_flex_link_collision'>
          <pose frame=''>0 0 0 0 -0 0</pose>
          <geometry>
            <mesh>
              <scale>1 1 1</scale>
              <uri>/opt/ros/kinetic/share/fetch_description/meshes/wrist_flex_link_collision.STL</uri>
            </mesh>
          </geometry>
          <max_contacts>10</max_contacts>
          <surface>
            <contact>
              <ode/>
            </contact>
            <bounce/>
            <friction>
              <torsional>
                <ode/>
              </torsional>
              <ode/>
            </friction>
          </surface>
        </collision>
        <visual name='wrist_flex_link_visual'>
          <pose frame=''>0 0 0 0 -0 0</pose>
          <geometry>
            <mesh>
              <scale>1 1 1</scale>
              <uri>/opt/ros/kinetic/share/fetch_description/meshes/wrist_flex_link.dae</uri>
            </mesh>
          </geometry>
        </visual>
        <self_collide>0</self_collide>
        <kinematic>0</kinematic>
        <gravity>1</gravity>
      </link>
      <joint name='wrist_flex_joint' type='revolute'>
        <child>wrist_flex_link</child>
        <parent>forearm_roll_link</parent>
        <axis>
          <xyz>0 1 0</xyz>
          <limit>
            <lower>-2.16</lower>
            <upper>2.16</upper>
            <effort>25.7</effort>
            <velocity>2.268</velocity>
          </limit>
          <dynamics>
            <damping>1</damping>
            <friction>0</friction>
            <spring_reference>0</spring_reference>
            <spring_stiffness>0</spring_stiffness>
          </dynamics>
          <use_parent_model_frame>1</use_parent_model_frame>
        </axis>
      </joint>
      <link name='wrist_roll_link'>
        <pose frame=''>0.96165 0 0.78601 0 -0 0</pose>
        <inertial>
          <pose frame=''>0.070966 -5.9e-05 -0.001577 0 -0 0</pose>
          <mass>1.6529</mass>
          <inertia>
            <ixx>0.00140031</ixx>
            <ixy>4.16123e-06</ixy>
            <ixz>1.24837e-05</ixz>
            <iyy>0.00255747</iyy>
            <iyz>-9.32314e-08</iyz>
            <izz>0.00305722</izz>
          </inertia>
        </inertial>
        <collision name='wrist_roll_link_collision'>
          <pose frame=''>0 0 0 0 -0 0</pose>
          <geometry>
            <mesh>
              <scale>1 1 1</scale>
              <uri>/opt/ros/kinetic/share/fetch_description/meshes/wrist_roll_link_collision.STL</uri>
            </mesh>
          </geometry>
          <max_contacts>10</max_contacts>
          <surface>
            <contact>
              <ode/>
            </contact>
            <bounce/>
            <friction>
              <torsional>
                <ode/>
              </torsional>
              <ode/>
            </friction>
          </surface>
        </collision>
        <collision name='wrist_roll_link_fixed_joint_lump__gripper_link_collision_1'>
          <pose frame=''>0.16645 0 0 0 -0 0</pose>
          <geometry>
            <mesh>
              <scale>1 1 1</scale>
              <uri>/opt/ros/kinetic/share/fetch_description/meshes/gripper_link.STL</uri>
            </mesh>
          </geometry>
          <max_contacts>10</max_contacts>
          <surface>
            <contact>
              <ode/>
            </contact>
            <bounce/>
            <friction>
              <torsional>
                <ode/>
              </torsional>
              <ode/>
            </friction>
          </surface>
        </collision>
        <visual name='wrist_roll_link_visual'>
          <pose frame=''>0 0 0 0 -0 0</pose>
          <geometry>
            <mesh>
              <scale>1 1 1</scale>
              <uri>/opt/ros/kinetic/share/fetch_description/meshes/wrist_roll_link.dae</uri>
            </mesh>
          </geometry>
        </visual>
        <visual name='wrist_roll_link_fixed_joint_lump__gripper_link_visual_1'>
          <pose frame=''>0.16645 0 0 0 -0 0</pose>
          <geometry>
            <mesh>
              <scale>1 1 1</scale>
              <uri>/opt/ros/kinetic/share/fetch_description/meshes/gripper_link.dae</uri>
            </mesh>
          </geometry>
        </visual>
        <self_collide>0</self_collide>
        <kinematic>0</kinematic>
        <gravity>1</gravity>
      </link>
      <joint name='wrist_roll_joint' type='revolute'>
        <child>wrist_roll_link</child>
        <parent>wrist_flex_link</parent>
        <axis>
          <xyz>1 0 0</xyz>
          <limit>
            <lower>-1e+16</lower>
            <upper>1e+16</upper>
          </limit>
          <dynamics>
            <damping>5</damping>
            <friction>0</friction>
            <spring_reference>0</spring_reference>
            <spring_stiffness>0</spring_stiffness>
          </dynamics>
          <use_parent_model_frame>1</use_parent_model_frame>
        </axis>
        <physics>
          <ode>
            <implicit_spring_damper>1</implicit_spring_damper>
            <cfm_damping>1</cfm_damping>
            <limit>
              <cfm>0</cfm>
              <erp>0.2</erp>
            </limit>
          </ode>
        </physics>
      </joint>
      <link name='l_gripper_finger_link'>
        <pose frame=''>1.1281 -0.015425 0.78601 0 -0 0</pose>
        <inertial>
          <pose frame=''>-0.01 0 0 0 -0 0</pose>
          <mass>0.0798</mass>
          <inertia>
            <ixx>0.002</ixx>
            <ixy>0</ixy>
            <ixz>0</ixz>
            <iyy>0</iyy>
            <iyz>0</iyz>
            <izz>0</izz>
          </inertia>
        </inertial>
        <collision name='l_gripper_finger_link_collision'>
          <pose frame=''>0 -0.101425 0 0 -0 0</pose>
          <geometry>
            <mesh>
              <scale>1 1 1</scale>
              <uri>/opt/ros/kinetic/share/fetch_description/meshes/l_gripper_finger_link.STL</uri>
            </mesh>
          </geometry>
          <surface>
            <contact>
              <ode>
                <kp>1e+06</kp>
                <kd>100</kd>
                <max_vel>1</max_vel>
                <min_depth>0.001</min_depth>
              </ode>
            </contact>
            <friction>
              <ode>
                <mu>30</mu>
                <mu2>30</mu2>
              </ode>
              <torsional>
                <ode/>
              </torsional>
            </friction>
            <bounce/>
          </surface>
          <max_contacts>10</max_contacts>
        </collision>
        <visual name='l_gripper_finger_link_visual'>
          <pose frame=''>0 -0.101425 0 0 -0 0</pose>
          <geometry>
            <mesh>
              <scale>1 1 1</scale>
              <uri>/opt/ros/kinetic/share/fetch_description/meshes/l_gripper_finger_link.STL</uri>
            </mesh>
          </geometry>
          <material>
            <script>
              <name>Gazebo/Grey</name>
              <uri>file://media/materials/scripts/gazebo.material</uri>
            </script>
          </material>
        </visual>
        <gravity>1</gravity>
        <velocity_decay/>
        <self_collide>0</self_collide>
        <kinematic>0</kinematic>
      </link>
      <joint name='l_gripper_finger_joint' type='prismatic'>
        <child>l_gripper_finger_link</child>
        <parent>wrist_roll_link</parent>
        <axis>
          <xyz>0 -1 0</xyz>
          <limit>
            <lower>0</lower>
            <upper>0.05</upper>
            <effort>60</effort>
            <velocity>0.05</velocity>
          </limit>
          <dynamics>
            <damping>100</damping>
            <friction>0</friction>
            <spring_reference>0</spring_reference>
            <spring_stiffness>0</spring_stiffness>
          </dynamics>
          <use_parent_model_frame>1</use_parent_model_frame>
        </axis>
      </joint>
      <link name='r_gripper_finger_link'>
        <pose frame=''>1.1281 0.015425 0.78601 0 -0 0</pose>
        <inertial>
          <pose frame=''>-0.01 0 0 0 -0 0</pose>
          <mass>0.0798</mass>
          <inertia>
            <ixx>0.002</ixx>
            <ixy>0</ixy>
            <ixz>0</ixz>
            <iyy>0</iyy>
            <iyz>0</iyz>
            <izz>0</izz>
          </inertia>
        </inertial>
        <collision name='r_gripper_finger_link_collision'>
          <pose frame=''>0 0.101425 0 0 -0 0</pose>
          <geometry>
            <mesh>
              <scale>1 1 1</scale>
              <uri>/opt/ros/kinetic/share/fetch_description/meshes/r_gripper_finger_link.STL</uri>
            </mesh>
          </geometry>
          <surface>
            <contact>
              <ode>
                <kp>1e+06</kp>
                <kd>100</kd>
                <max_vel>1</max_vel>
                <min_depth>0.001</min_depth>
              </ode>
            </contact>
            <friction>
              <ode>
                <mu>30</mu>
                <mu2>30</mu2>
              </ode>
              <torsional>
                <ode/>
              </torsional>
            </friction>
            <bounce/>
          </surface>
          <max_contacts>10</max_contacts>
        </collision>
        <visual name='r_gripper_finger_link_visual'>
          <pose frame=''>0 0.101425 0 0 -0 0</pose>
          <geometry>
            <mesh>
              <scale>1 1 1</scale>
              <uri>/opt/ros/kinetic/share/fetch_description/meshes/r_gripper_finger_link.STL</uri>
            </mesh>
          </geometry>
          <material>
            <script>
              <name>Gazebo/Grey</name>
              <uri>file://media/materials/scripts/gazebo.material</uri>
            </script>
          </material>
        </visual>
        <gravity>1</gravity>
        <velocity_decay/>
        <self_collide>0</self_collide>
        <kinematic>0</kinematic>
      </link>
      <joint name='r_gripper_finger_joint' type='prismatic'>
        <child>r_gripper_finger_link</child>
        <parent>wrist_roll_link</parent>
        <axis>
          <xyz>0 1 -0</xyz>
          <limit>
            <lower>0</lower>
            <upper>0.05</upper>
            <effort>60</effort>
            <velocity>0.05</velocity>
          </limit>
          <dynamics>
            <damping>100</damping>
            <friction>0</friction>
            <spring_reference>0</spring_reference>
            <spring_stiffness>0</spring_stiffness>
          </dynamics>
          <use_parent_model_frame>1</use_parent_model_frame>
        </axis>
      </joint>
      <plugin name='fetch_gazebo_plugin' filename='libfetch_gazebo_plugin.so'>
        <robotNamespace>/</robotNamespace>
      </plugin>
      <static>0</static>
      <plugin name='ground_truth' filename='libgazebo_ros_p3d.so'>
        <frameName>world</frameName>
        <bodyName>base_link</bodyName>
        <topicName>odom_fake</topicName>
        <updateRate>30.0</updateRate>
        <robotNamespace>/</robotNamespace>
      </plugin>
      <pose frame=''>-0.5 1 0 0 -0 1.57</pose>
    </model>
  </world>
</sdf>
